I'm sorry, but an uncaught exception occurred.

While running game code:
  File "game/test_obj_char_elena_petrovic.rpy", line 5, in script
    init -998 python:
  File "game/test_obj_char_elena_petrovic.rpy", line 34, in <module>
    si = elena.new_group("sins",3)
TypeError: new_group() takes 2 positional arguments but 3 were given

-- Full Traceback ------------------------------------------------------------

Full traceback:
  File "game/test_obj_char_elena_petrovic.rpy", line 5, in script
    init -998 python:
  File "C:\2022portable_programs\renpy-8.3.4-sdk modified\renpy\ast.py", line 827, in execute
    renpy.python.py_exec_bytecode(self.code.bytecode, self.hide, store=self.store)
  File "C:\2022portable_programs\renpy-8.3.4-sdk modified\renpy\python.py", line 1178, in py_exec_bytecode
    exec(bytecode, globals, locals)
  File "game/test_obj_char_elena_petrovic.rpy", line 34, in <module>
    si = elena.new_group("sins",3)
TypeError: new_group() takes 2 positional arguments but 3 were given

Windows-10-10.0.19045 AMD64
Ren'Py 8.3.4.24120703
freezing_love_1 1.0
Wed Jan  8 20:47:02 2025
